Waiting for JIT...
Using 1 devices for parallel training.
Epoch 1/20000, Num Batches: 8152
Traced<ShapedArray(float32[])>with<DynamicJaxprTrace(level=3/1)>
Traceback (most recent call last):
  File "/Users/akshayjacobthomas/anaconda3/envs/jax_trial/lib/python3.9/site-packages/ml_collections/config_dict/config_dict.py", line 903, in __getitem__
    field = self._fields[key]
KeyError: 'save_epoch'
During handling of the above exception, another exception occurred:
Traceback (most recent call last):
  File "/Users/akshayjacobthomas/anaconda3/envs/jax_trial/lib/python3.9/site-packages/ml_collections/config_dict/config_dict.py", line 827, in __getattr__
    return self[attribute]
  File "/Users/akshayjacobthomas/anaconda3/envs/jax_trial/lib/python3.9/site-packages/ml_collections/config_dict/config_dict.py", line 909, in __getitem__
    raise KeyError(self._generate_did_you_mean_message(key, str(e)))
KeyError: "'save_epoch'"
During handling of the above exception, another exception occurred:
Traceback (most recent call last):
  File "/Users/akshayjacobthomas/Documents/GitHub/DiffMicromehanics/surrogate/main.py", line 40, in <module>
    app.run(main)
  File "/Users/akshayjacobthomas/anaconda3/envs/jax_trial/lib/python3.9/site-packages/absl/app.py", line 308, in run
    _run_main(main, args)
  File "/Users/akshayjacobthomas/anaconda3/envs/jax_trial/lib/python3.9/site-packages/absl/app.py", line 254, in _run_main
    sys.exit(main(argv))
  File "/Users/akshayjacobthomas/Documents/GitHub/DiffMicromehanics/surrogate/main.py", line 32, in main
    train.train_and_evaluate(FLAGS.config, FLAGS.workdir)
  File "/Users/akshayjacobthomas/Documents/GitHub/DiffMicromehanics/surrogate/train.py", line 100, in train_and_evaluate
    if jax.process_index() == 0 and (i % config.logging.save_epoch== 0):
  File "/Users/akshayjacobthomas/anaconda3/envs/jax_trial/lib/python3.9/site-packages/ml_collections/config_dict/config_dict.py", line 829, in __getattr__
    raise AttributeError(e)
AttributeError: "'save_epoch'"